grader@Lohy:~$ sudo tail /var/log/apache2/error.log
[sudo] password for grader:
[Tue Jan 22 16:44:37.544143 2019] [wsgi:error] [pid 11637:tid 139748763465472] [remote 51.218.215.5:57539] Traceback (most recent call last):
[Tue Jan 22 16:44:37.544163 2019] [wsgi:error] [pid 11637:tid 139748763465472] [remote 51.218.215.5:57539]   File "/var/www/catalog/catalog.wsgi", line 7, in <module>
[Tue Jan 22 16:44:37.544192 2019] [wsgi:error] [pid 11637:tid 139748763465472] [remote 51.218.215.5:57539]     from catalog import app as application
[Tue Jan 22 16:44:37.544201 2019] [wsgi:error] [pid 11637:tid 139748763465472] [remote 51.218.215.5:57539]   File "/var/www/catalog/catalog/__init__.py", line 25, in <module>
[Tue Jan 22 16:44:37.544216 2019] [wsgi:error] [pid 11637:tid 139748763465472] [remote 51.218.215.5:57539]     open('/var/www/catalog/catalog/client_secrets.json', 'r').read())['web']['client_id']
[Tue Jan 22 16:44:37.544225 2019] [wsgi:error] [pid 11637:tid 139748763465472] [remote 51.218.215.5:57539]   File "/usr/lib/python2.7/json/__init__.py", line 339, in loads
[Tue Jan 22 16:44:37.544241 2019] [wsgi:error] [pid 11637:tid 139748763465472] [remote 51.218.215.5:57539]     return _default_decoder.decode(s)
[Tue Jan 22 16:44:37.544248 2019] [wsgi:error] [pid 11637:tid 139748763465472] [remote 51.218.215.5:57539]   File "/usr/lib/python2.7/json/decoder.py", line 367, in decode
[Tue Jan 22 16:44:37.544273 2019] [wsgi:error] [pid 11637:tid 139748763465472] [remote 51.218.215.5:57539]     raise ValueError(errmsg("Extra data", s, end, len(s)))
[Tue Jan 22 16:44:37.544292 2019] [wsgi:error] [pid 11637:tid 139748763465472] [remote 51.218.215.5:57539] ValueError: Extra data: line 1 column 13 - line 2 column 1 (char 12 - 73)
